{
 "cells": [
  {
   "cell_type": "markdown",
   "metadata": {},
   "source": [
    "## INSTALL LIBRARY"
   ]
  },
  {
   "cell_type": "markdown",
   "metadata": {},
   "source": [
    "- pip install redis"
   ]
  },
  {
   "cell_type": "code",
   "execution_count": 1,
   "metadata": {},
   "outputs": [
    {
     "name": "stdout",
     "output_type": "stream",
     "text": [
      "Collecting redis\n",
      "  Downloading redis-5.0.6-py3-none-any.whl.metadata (9.3 kB)\n",
      "Collecting async-timeout>=4.0.3 (from redis)\n",
      "  Downloading async_timeout-4.0.3-py3-none-any.whl.metadata (4.2 kB)\n",
      "Downloading redis-5.0.6-py3-none-any.whl (252 kB)\n",
      "\u001b[2K   \u001b[90m━━━━━━━━━━━━━━━━━━━━━━━━━━━━━━━━━━━━━━━\u001b[0m \u001b[32m252.0/252.0 kB\u001b[0m \u001b[31m359.8 kB/s\u001b[0m eta \u001b[36m0:00:00\u001b[0m00:01\u001b[0m00:01\u001b[0m\n",
      "\u001b[?25hDownloading async_timeout-4.0.3-py3-none-any.whl (5.7 kB)\n",
      "Installing collected packages: async-timeout, redis\n",
      "Successfully installed async-timeout-4.0.3 redis-5.0.6\n",
      "\u001b[33mWARNING: Running pip as the 'root' user can result in broken permissions and conflicting behaviour with the system package manager. It is recommended to use a virtual environment instead: https://pip.pypa.io/warnings/venv\u001b[0m\u001b[33m\n",
      "\u001b[0m"
     ]
    }
   ],
   "source": [
    "!pip3 install redis\n"
   ]
  },
  {
   "cell_type": "markdown",
   "metadata": {},
   "source": [
    "## IMPORT LIBRARY"
   ]
  },
  {
   "cell_type": "code",
   "execution_count": 2,
   "metadata": {},
   "outputs": [],
   "source": [
    "import redis"
   ]
  },
  {
   "cell_type": "markdown",
   "metadata": {},
   "source": [
    "## CREATE CONNECTION\n"
   ]
  },
  {
   "cell_type": "code",
   "execution_count": 3,
   "metadata": {},
   "outputs": [],
   "source": [
    "# Redis connection parameters\n",
    "redis_host = 'localhost'\n",
    "redis_port = 6379\n",
    "redis_password = None  # If your Redis server doesn't require a password, set this to None\n",
    "\n",
    "# Connect to Redis server\n",
    "redis_client = redis.Redis(host=redis_host, port=redis_port, password=redis_password)"
   ]
  },
  {
   "cell_type": "markdown",
   "metadata": {},
   "source": [
    "## INSERT DATA\n"
   ]
  },
  {
   "cell_type": "code",
   "execution_count": null,
   "metadata": {},
   "outputs": [],
   "source": []
  },
  {
   "cell_type": "markdown",
   "metadata": {},
   "source": [
    "## QUERY DATA\n"
   ]
  },
  {
   "cell_type": "code",
   "execution_count": 8,
   "metadata": {},
   "outputs": [
    {
     "ename": "ConnectionError",
     "evalue": "Error 111 connecting to localhost:6379. Connection refused.",
     "output_type": "error",
     "traceback": [
      "\u001b[0;31m---------------------------------------------------------------------------\u001b[0m",
      "\u001b[0;31mConnectionRefusedError\u001b[0m                    Traceback (most recent call last)",
      "File \u001b[0;32m/usr/local/lib/python3.10/dist-packages/redis/connection.py:276\u001b[0m, in \u001b[0;36mAbstractConnection.connect\u001b[0;34m(self)\u001b[0m\n\u001b[1;32m    275\u001b[0m \u001b[38;5;28;01mtry\u001b[39;00m:\n\u001b[0;32m--> 276\u001b[0m     sock \u001b[38;5;241m=\u001b[39m \u001b[38;5;28;43mself\u001b[39;49m\u001b[38;5;241;43m.\u001b[39;49m\u001b[43mretry\u001b[49m\u001b[38;5;241;43m.\u001b[39;49m\u001b[43mcall_with_retry\u001b[49m\u001b[43m(\u001b[49m\n\u001b[1;32m    277\u001b[0m \u001b[43m        \u001b[49m\u001b[38;5;28;43;01mlambda\u001b[39;49;00m\u001b[43m:\u001b[49m\u001b[43m \u001b[49m\u001b[38;5;28;43mself\u001b[39;49m\u001b[38;5;241;43m.\u001b[39;49m\u001b[43m_connect\u001b[49m\u001b[43m(\u001b[49m\u001b[43m)\u001b[49m\u001b[43m,\u001b[49m\u001b[43m \u001b[49m\u001b[38;5;28;43;01mlambda\u001b[39;49;00m\u001b[43m \u001b[49m\u001b[43merror\u001b[49m\u001b[43m:\u001b[49m\u001b[43m \u001b[49m\u001b[38;5;28;43mself\u001b[39;49m\u001b[38;5;241;43m.\u001b[39;49m\u001b[43mdisconnect\u001b[49m\u001b[43m(\u001b[49m\u001b[43merror\u001b[49m\u001b[43m)\u001b[49m\n\u001b[1;32m    278\u001b[0m \u001b[43m    \u001b[49m\u001b[43m)\u001b[49m\n\u001b[1;32m    279\u001b[0m \u001b[38;5;28;01mexcept\u001b[39;00m socket\u001b[38;5;241m.\u001b[39mtimeout:\n",
      "File \u001b[0;32m/usr/local/lib/python3.10/dist-packages/redis/retry.py:46\u001b[0m, in \u001b[0;36mRetry.call_with_retry\u001b[0;34m(self, do, fail)\u001b[0m\n\u001b[1;32m     45\u001b[0m \u001b[38;5;28;01mtry\u001b[39;00m:\n\u001b[0;32m---> 46\u001b[0m     \u001b[38;5;28;01mreturn\u001b[39;00m \u001b[43mdo\u001b[49m\u001b[43m(\u001b[49m\u001b[43m)\u001b[49m\n\u001b[1;32m     47\u001b[0m \u001b[38;5;28;01mexcept\u001b[39;00m \u001b[38;5;28mself\u001b[39m\u001b[38;5;241m.\u001b[39m_supported_errors \u001b[38;5;28;01mas\u001b[39;00m error:\n",
      "File \u001b[0;32m/usr/local/lib/python3.10/dist-packages/redis/connection.py:277\u001b[0m, in \u001b[0;36mAbstractConnection.connect.<locals>.<lambda>\u001b[0;34m()\u001b[0m\n\u001b[1;32m    275\u001b[0m \u001b[38;5;28;01mtry\u001b[39;00m:\n\u001b[1;32m    276\u001b[0m     sock \u001b[38;5;241m=\u001b[39m \u001b[38;5;28mself\u001b[39m\u001b[38;5;241m.\u001b[39mretry\u001b[38;5;241m.\u001b[39mcall_with_retry(\n\u001b[0;32m--> 277\u001b[0m         \u001b[38;5;28;01mlambda\u001b[39;00m: \u001b[38;5;28;43mself\u001b[39;49m\u001b[38;5;241;43m.\u001b[39;49m\u001b[43m_connect\u001b[49m\u001b[43m(\u001b[49m\u001b[43m)\u001b[49m, \u001b[38;5;28;01mlambda\u001b[39;00m error: \u001b[38;5;28mself\u001b[39m\u001b[38;5;241m.\u001b[39mdisconnect(error)\n\u001b[1;32m    278\u001b[0m     )\n\u001b[1;32m    279\u001b[0m \u001b[38;5;28;01mexcept\u001b[39;00m socket\u001b[38;5;241m.\u001b[39mtimeout:\n",
      "File \u001b[0;32m/usr/local/lib/python3.10/dist-packages/redis/connection.py:639\u001b[0m, in \u001b[0;36mConnection._connect\u001b[0;34m(self)\u001b[0m\n\u001b[1;32m    638\u001b[0m \u001b[38;5;28;01mif\u001b[39;00m err \u001b[38;5;129;01mis\u001b[39;00m \u001b[38;5;129;01mnot\u001b[39;00m \u001b[38;5;28;01mNone\u001b[39;00m:\n\u001b[0;32m--> 639\u001b[0m     \u001b[38;5;28;01mraise\u001b[39;00m err\n\u001b[1;32m    640\u001b[0m \u001b[38;5;28;01mraise\u001b[39;00m \u001b[38;5;167;01mOSError\u001b[39;00m(\u001b[38;5;124m\"\u001b[39m\u001b[38;5;124msocket.getaddrinfo returned an empty list\u001b[39m\u001b[38;5;124m\"\u001b[39m)\n",
      "File \u001b[0;32m/usr/local/lib/python3.10/dist-packages/redis/connection.py:627\u001b[0m, in \u001b[0;36mConnection._connect\u001b[0;34m(self)\u001b[0m\n\u001b[1;32m    626\u001b[0m \u001b[38;5;66;03m# connect\u001b[39;00m\n\u001b[0;32m--> 627\u001b[0m \u001b[43msock\u001b[49m\u001b[38;5;241;43m.\u001b[39;49m\u001b[43mconnect\u001b[49m\u001b[43m(\u001b[49m\u001b[43msocket_address\u001b[49m\u001b[43m)\u001b[49m\n\u001b[1;32m    629\u001b[0m \u001b[38;5;66;03m# set the socket_timeout now that we're connected\u001b[39;00m\n",
      "\u001b[0;31mConnectionRefusedError\u001b[0m: [Errno 111] Connection refused",
      "\nDuring handling of the above exception, another exception occurred:\n",
      "\u001b[0;31mConnectionError\u001b[0m                           Traceback (most recent call last)",
      "Cell \u001b[0;32mIn[8], line 1\u001b[0m\n\u001b[0;32m----> 1\u001b[0m name \u001b[38;5;241m=\u001b[39m \u001b[43mredis_client\u001b[49m\u001b[38;5;241;43m.\u001b[39;49m\u001b[43mget\u001b[49m\u001b[43m(\u001b[49m\u001b[38;5;124;43m'\u001b[39;49m\u001b[38;5;124;43mname\u001b[39;49m\u001b[38;5;124;43m'\u001b[39;49m\u001b[43m)\u001b[49m\u001b[38;5;241m.\u001b[39mdecode(\u001b[38;5;124m'\u001b[39m\u001b[38;5;124mutf-8\u001b[39m\u001b[38;5;124m'\u001b[39m)\n\u001b[1;32m      2\u001b[0m age \u001b[38;5;241m=\u001b[39m redis_client\u001b[38;5;241m.\u001b[39mget(\u001b[38;5;124m'\u001b[39m\u001b[38;5;124mage\u001b[39m\u001b[38;5;124m'\u001b[39m)\u001b[38;5;241m.\u001b[39mdecode(\u001b[38;5;124m'\u001b[39m\u001b[38;5;124mutf-8\u001b[39m\u001b[38;5;124m'\u001b[39m)\n\u001b[1;32m      4\u001b[0m \u001b[38;5;28mprint\u001b[39m(\u001b[38;5;124m\"\u001b[39m\u001b[38;5;124mName:\u001b[39m\u001b[38;5;124m\"\u001b[39m, name)\n",
      "File \u001b[0;32m/usr/local/lib/python3.10/dist-packages/redis/commands/core.py:1830\u001b[0m, in \u001b[0;36mBasicKeyCommands.get\u001b[0;34m(self, name)\u001b[0m\n\u001b[1;32m   1824\u001b[0m \u001b[38;5;28;01mdef\u001b[39;00m \u001b[38;5;21mget\u001b[39m(\u001b[38;5;28mself\u001b[39m, name: KeyT) \u001b[38;5;241m-\u001b[39m\u001b[38;5;241m>\u001b[39m ResponseT:\n\u001b[1;32m   1825\u001b[0m \u001b[38;5;250m    \u001b[39m\u001b[38;5;124;03m\"\"\"\u001b[39;00m\n\u001b[1;32m   1826\u001b[0m \u001b[38;5;124;03m    Return the value at key ``name``, or None if the key doesn't exist\u001b[39;00m\n\u001b[1;32m   1827\u001b[0m \n\u001b[1;32m   1828\u001b[0m \u001b[38;5;124;03m    For more information see https://redis.io/commands/get\u001b[39;00m\n\u001b[1;32m   1829\u001b[0m \u001b[38;5;124;03m    \"\"\"\u001b[39;00m\n\u001b[0;32m-> 1830\u001b[0m     \u001b[38;5;28;01mreturn\u001b[39;00m \u001b[38;5;28;43mself\u001b[39;49m\u001b[38;5;241;43m.\u001b[39;49m\u001b[43mexecute_command\u001b[49m\u001b[43m(\u001b[49m\u001b[38;5;124;43m\"\u001b[39;49m\u001b[38;5;124;43mGET\u001b[39;49m\u001b[38;5;124;43m\"\u001b[39;49m\u001b[43m,\u001b[49m\u001b[43m \u001b[49m\u001b[43mname\u001b[49m\u001b[43m)\u001b[49m\n",
      "File \u001b[0;32m/usr/local/lib/python3.10/dist-packages/redis/client.py:542\u001b[0m, in \u001b[0;36mRedis.execute_command\u001b[0;34m(self, *args, **options)\u001b[0m\n\u001b[1;32m    540\u001b[0m pool \u001b[38;5;241m=\u001b[39m \u001b[38;5;28mself\u001b[39m\u001b[38;5;241m.\u001b[39mconnection_pool\n\u001b[1;32m    541\u001b[0m command_name \u001b[38;5;241m=\u001b[39m args[\u001b[38;5;241m0\u001b[39m]\n\u001b[0;32m--> 542\u001b[0m conn \u001b[38;5;241m=\u001b[39m \u001b[38;5;28mself\u001b[39m\u001b[38;5;241m.\u001b[39mconnection \u001b[38;5;129;01mor\u001b[39;00m \u001b[43mpool\u001b[49m\u001b[38;5;241;43m.\u001b[39;49m\u001b[43mget_connection\u001b[49m\u001b[43m(\u001b[49m\u001b[43mcommand_name\u001b[49m\u001b[43m,\u001b[49m\u001b[43m \u001b[49m\u001b[38;5;241;43m*\u001b[39;49m\u001b[38;5;241;43m*\u001b[39;49m\u001b[43moptions\u001b[49m\u001b[43m)\u001b[49m\n\u001b[1;32m    544\u001b[0m \u001b[38;5;28;01mtry\u001b[39;00m:\n\u001b[1;32m    545\u001b[0m     \u001b[38;5;28;01mreturn\u001b[39;00m conn\u001b[38;5;241m.\u001b[39mretry\u001b[38;5;241m.\u001b[39mcall_with_retry(\n\u001b[1;32m    546\u001b[0m         \u001b[38;5;28;01mlambda\u001b[39;00m: \u001b[38;5;28mself\u001b[39m\u001b[38;5;241m.\u001b[39m_send_command_parse_response(\n\u001b[1;32m    547\u001b[0m             conn, command_name, \u001b[38;5;241m*\u001b[39margs, \u001b[38;5;241m*\u001b[39m\u001b[38;5;241m*\u001b[39moptions\n\u001b[1;32m    548\u001b[0m         ),\n\u001b[1;32m    549\u001b[0m         \u001b[38;5;28;01mlambda\u001b[39;00m error: \u001b[38;5;28mself\u001b[39m\u001b[38;5;241m.\u001b[39m_disconnect_raise(conn, error),\n\u001b[1;32m    550\u001b[0m     )\n",
      "File \u001b[0;32m/usr/local/lib/python3.10/dist-packages/redis/connection.py:1109\u001b[0m, in \u001b[0;36mConnectionPool.get_connection\u001b[0;34m(self, command_name, *keys, **options)\u001b[0m\n\u001b[1;32m   1105\u001b[0m     \u001b[38;5;28mself\u001b[39m\u001b[38;5;241m.\u001b[39m_in_use_connections\u001b[38;5;241m.\u001b[39madd(connection)\n\u001b[1;32m   1107\u001b[0m \u001b[38;5;28;01mtry\u001b[39;00m:\n\u001b[1;32m   1108\u001b[0m     \u001b[38;5;66;03m# ensure this connection is connected to Redis\u001b[39;00m\n\u001b[0;32m-> 1109\u001b[0m     \u001b[43mconnection\u001b[49m\u001b[38;5;241;43m.\u001b[39;49m\u001b[43mconnect\u001b[49m\u001b[43m(\u001b[49m\u001b[43m)\u001b[49m\n\u001b[1;32m   1110\u001b[0m     \u001b[38;5;66;03m# connections that the pool provides should be ready to send\u001b[39;00m\n\u001b[1;32m   1111\u001b[0m     \u001b[38;5;66;03m# a command. if not, the connection was either returned to the\u001b[39;00m\n\u001b[1;32m   1112\u001b[0m     \u001b[38;5;66;03m# pool before all data has been read or the socket has been\u001b[39;00m\n\u001b[1;32m   1113\u001b[0m     \u001b[38;5;66;03m# closed. either way, reconnect and verify everything is good.\u001b[39;00m\n\u001b[1;32m   1114\u001b[0m     \u001b[38;5;28;01mtry\u001b[39;00m:\n",
      "File \u001b[0;32m/usr/local/lib/python3.10/dist-packages/redis/connection.py:282\u001b[0m, in \u001b[0;36mAbstractConnection.connect\u001b[0;34m(self)\u001b[0m\n\u001b[1;32m    280\u001b[0m     \u001b[38;5;28;01mraise\u001b[39;00m \u001b[38;5;167;01mTimeoutError\u001b[39;00m(\u001b[38;5;124m\"\u001b[39m\u001b[38;5;124mTimeout connecting to server\u001b[39m\u001b[38;5;124m\"\u001b[39m)\n\u001b[1;32m    281\u001b[0m \u001b[38;5;28;01mexcept\u001b[39;00m \u001b[38;5;167;01mOSError\u001b[39;00m \u001b[38;5;28;01mas\u001b[39;00m e:\n\u001b[0;32m--> 282\u001b[0m     \u001b[38;5;28;01mraise\u001b[39;00m \u001b[38;5;167;01mConnectionError\u001b[39;00m(\u001b[38;5;28mself\u001b[39m\u001b[38;5;241m.\u001b[39m_error_message(e))\n\u001b[1;32m    284\u001b[0m \u001b[38;5;28mself\u001b[39m\u001b[38;5;241m.\u001b[39m_sock \u001b[38;5;241m=\u001b[39m sock\n\u001b[1;32m    285\u001b[0m \u001b[38;5;28;01mtry\u001b[39;00m:\n",
      "\u001b[0;31mConnectionError\u001b[0m: Error 111 connecting to localhost:6379. Connection refused."
     ]
    }
   ],
   "source": [
    "name = redis_client.get('name').decode('utf-8')\n",
    "age = redis_client.get('age').decode('utf-8')\n",
    "\n",
    "print(\"Name:\", name)\n",
    "print(\"Age:\", age)"
   ]
  }
 ],
 "metadata": {
  "language_info": {
   "name": "python"
  }
 },
 "nbformat": 4,
 "nbformat_minor": 2
}
